<?xml version="1.0"?>
<robot name="table"
       xmlns:xi="http://www.w3.org/2001/XInclude"
       xmlns:gazebo="http://playerstage.sourceforge.net/gazebo/xmlschema/#gz"
       xmlns:model="http://playerstage.sourceforge.net/gazebo/xmlschema/#model"
       xmlns:sensor="http://playerstage.sourceforge.net/gazebo/xmlschema/#sensor"
       xmlns:body="http://playerstage.sourceforge.net/gazebo/xmlschema/#body"
       xmlns:geom="http://playerstage.sourceforge.net/gazebo/xmlschema/#geom"
       xmlns:joint="http://playerstage.sourceforge.net/gazebo/xmlschema/#joint"
       xmlns:interface="http://playerstage.sourceforge.net/gazebo/xmlschema/#interface"
       xmlns:rendering="http://playerstage.sourceforge.net/gazebo/xmlschema/#rendering"
       xmlns:renderable="http://playerstage.sourceforge.net/gazebo/xmlschema/#renderable"
       xmlns:controller="http://playerstage.sourceforge.net/gazebo/xmlschema/#controller"
       xmlns:physics="http://playerstage.sourceforge.net/gazebo/xmlschema/#physics">

  <property name="table_height" value="0.55" />
  <property name="table_width" value="1.0" />
  <property name="table_depth" value="1.0" />
  <property name="leg_radius" value="0.02" />
  <property name="table_x" value="9.98" />
  <property name="table_y" value="0.0" />
  <property name="table_z" value="0.0" />


  <property name="M_PI" value="3.1415926535897931" />


  <!-- link blocks -->
  <joint name="table_top_joint" type="planar" >
    <parent link="world" />
    <origin xyz="${table_x} ${table_y} ${table_z+table_height+0.01}" rpy="0 0 0" />
    <child link="table_top_link" />
  </joint>
  <link name="table_top_link">
    <inertial>
      <mass value="10" />
      <origin xyz="0 0 0.0" />
      <inertia ixx="1" ixy="0"  ixz="0"
               iyy="1" iyz="0"
               izz="1" />
    </inertial> 
    <visual>
      <origin xyz="0 0 0.0" rpy="0 0 0" />
      <geometry name="floor_visual_geom">
        <box size="${table_width} ${table_depth} 0.05" />
      </geometry>
    </visual> 
    <collision>
      <origin xyz="0 0 0.0" rpy="0.0 0.0 0.0" />
      <geometry name="floor_collision_geom">
        <box size="${table_width} ${table_depth} 0.05" />
      </geometry>
    </collision>
  </link>
  <gazebo reference="table_top_link">
    <material>Gazebo/LightWood</material>
    <mu1>50.0</mu1>
    <mu2>50.0</mu2>
    <kp>1000000.0</kp>
    <kd>1.0</kd>
  </gazebo>

  <joint name="leg1_joint" type="fixed" >
    <parent link="table_top_link" />
    <origin xyz="${table_width/2} ${table_depth/2} 0" rpy="0 0 0" />
    <child link="leg1_link" />
  </joint> 
  <link name="leg1_link">
    <inertial>
      <mass value="100" />
      <origin xyz="0 0 ${-table_height/2}" />
      <inertia ixx="0.1" ixy="0"  ixz="0"
               iyy="0.1" iyz="0"
               izz="0.01" />
    </inertial> 
    <visual>
      <origin xyz="0.0 0.0 ${-table_height/2}" rpy="0 0 0" />
      <geometry name="leg1_visual_geom">
        <cylinder radius="${leg_radius}" length="${table_height}" />
      </geometry>
    </visual> 
    <collision>
      <origin xyz="0.0 0.0 ${-table_height/2}" rpy="0.0 0.0 0.0" />
      <geometry name="leg1_collision_geom">
        <cylinder radius="${leg_radius}" length="${table_height}" />
      </geometry>
    </collision>
  </link>
  <gazebo reference="leg1_link">
    <material>Gazebo/Red</material>
    <mu1>1000.0</mu1>
    <mu2>1000.0</mu2>
    <kp>10000000.0</kp>
    <kd>1.0</kd>
    <selfCollide>true</selfCollide>
  </gazebo>

  <joint name="leg2_joint" type="fixed" >
    <parent link="table_top_link" />
    <origin xyz="${-table_width/2} ${table_depth/2} 0" rpy="0 0 0" />
    <child link="leg2_link" />
  </joint> 
  <link name="leg2_link">
    <inertial>
      <mass value="100" />
      <origin xyz="0 0 ${-table_height/2}" />
      <inertia ixx="0.1" ixy="0"  ixz="0"
               iyy="0.1" iyz="0"
               izz="0.01" />
    </inertial> 
    <visual>
      <origin xyz="0.0 0.0 ${-table_height/2}" rpy="0 0 0" />
      <geometry name="leg2_visual_geom">
        <cylinder radius="${leg_radius}" length="${table_height}" />
      </geometry>
    </visual> 
    <collision>
      <origin xyz="0.0 0.0 ${-table_height/2}" rpy="0.0 0.0 0.0" />
      <geometry name="leg2_collision_geom">
        <cylinder radius="${leg_radius}" length="${table_height}" />
      </geometry>
    </collision>
  </link>
  <gazebo reference="leg2_link">
    <material>Gazebo/Red</material>
    <mu1>1000.0</mu1>
    <mu2>1000.0</mu2>
    <kp>10000000.0</kp>
    <kd>1.0</kd>
    <selfCollide>true</selfCollide>
  </gazebo>

  <joint name="leg3_joint" type="fixed" >
    <parent link="table_top_link" />
    <origin xyz="${table_width/2} ${-table_depth/2} 0" rpy="0 0 0" />
    <child link="leg3_link" />
  </joint> 
  <link name="leg3_link">
    <inertial>
      <mass value="100" />
      <origin xyz="0 0 ${-table_height/2}" />
      <inertia ixx="0.1" ixy="0"  ixz="0"
               iyy="0.1" iyz="0"
               izz="0.01" />
    </inertial> 
    <visual>
      <origin xyz="0.0 0.0 ${-table_height/2}" rpy="0 0 0" />
      <geometry name="leg3_visual_geom">
        <cylinder radius="${leg_radius}" length="${table_height}" />
      </geometry>
    </visual> 
    <collision>
      <origin xyz="0.0 0.0 ${-table_height/2}" rpy="0.0 0.0 0.0" />
      <geometry name="leg3_collision_geom">
        <cylinder radius="${leg_radius}" length="${table_height}" />
      </geometry>
    </collision>
  </link>
  <gazebo reference="leg3_link">
    <material>Gazebo/Red</material>
    <mu1>1000.0</mu1>
    <mu2>1000.0</mu2>
    <kp>10000000.0</kp>
    <kd>1.0</kd>
    <selfCollide>true</selfCollide>
  </gazebo>

  <joint name="leg4_joint" type="fixed" >
    <parent link="table_top_link" />
    <origin xyz="${-table_width/2} ${-table_depth/2} 0" rpy="0 0 0" />
    <child link="leg4_link" />
  </joint> 
  <link name="leg4_link">
    <inertial>
      <mass value="100" />
      <origin xyz="0 0 ${-table_height/2}" />
      <inertia ixx="0.1" ixy="0"  ixz="0"
               iyy="0.1" iyz="0"
               izz="0.01" />
    </inertial> 
    <visual>
      <origin xyz="0.0 0.0 ${-table_height/2}" rpy="0 0 0" />
      <geometry name="leg4_visual_geom">
        <cylinder radius="${leg_radius}" length="${table_height}" />
      </geometry>
    </visual> 
    <collision>
      <origin xyz="0.0 0.0 ${-table_height/2}" rpy="0.0 0.0 0.0" />
      <geometry name="leg4_collision_geom">
        <cylinder radius="${leg_radius}" length="${table_height}" />
      </geometry>
    </collision>
  </link>
  <gazebo reference="leg4_link">
    <material>Gazebo/Red</material>
    <mu1>1000.0</mu1>
    <mu2>1000.0</mu2>
    <kp>10000000.0</kp>
    <kd>1.0</kd>
    <selfCollide>true</selfCollide>
  </gazebo>


  <!--
  <property name="object_1_x" value="0.96" />
  <property name="object_1_y" value="0.0" />

  <property name="object_1_height"      value="0.12" />
  <property name="object_1_radius"      value="0.02" />
  <property name="object_1_base_height" value="0.02" />
  <property name="object_1_base_width"  value="0.15" />
  <property name="object_1_mass"        value="1.0" /> 
  <property name="object_1_mu"          value="500.0" /> 
  <joint name="object_1_joint" type="fixed" >
    <parent link="object_1_base_link" />
    <origin xyz="0 0 ${object_1_base_height}" rpy="0 0 0" />
    <child link="object_1_link" />
  </joint> 
  <link name="object_1_link">
    <inertial>
      <mass value="${object_1_mass/2.0}" />
      <origin xyz="0 0 ${object_1_height/2}" />
      <inertia ixx="${object_1_mass/20.0}" ixy="0"  ixz="0"
               iyy="${object_1_mass/20.0}" iyz="0"
               izz="${object_1_mass/200.}" />
    </inertial> 
    <visual>
      <origin xyz="0.0 0.0 ${object_1_height/2}" rpy="0 0 0" />
      <geometry name="object_1_visual_geom">
        <cylinder radius="${object_1_radius}" length="${object_1_height}" />
      </geometry>
    </visual> 
    <collision>
      <origin xyz="0.0 0.0 ${object_1_height/2}" rpy="0.0 0.0 0.0" />
      <geometry name="object_1_collision_geom">
        <cylinder radius="${object_1_radius}" length="${object_1_height}" />
      </geometry>
    </collision>
  </link>
  <gazebo reference="object_1_link">
    <material>Gazebo/BumpyMetal</material>
    <mu1>${object_1_mu}</mu1>
    <mu2>${object_1_mu}</mu2>
    <kp>100000000.0</kp>
    <kd>1.0</kd>
    <selfCollide>true</selfCollide>
    <turnGravityOff>false</turnGravityOff>
    <dampingFactor>0.01</dampingFactor>
  </gazebo>

  <joint name="object_1_base_joint" type="planar" >
    <parent link="world" />
    <origin xyz="${object_1_x} ${object_1_y} ${table_z+table_height+0.03}" rpy="0 0 0" />
    <child link="object_1_base_link" />
  </joint> 
  <link name="object_1_base_link">
    <inertial>
      <mass value="${object_1_mass/2.0}" />
      <origin xyz="0 0 ${object_1_base_height/2}" />
      <inertia ixx="${object_1_mass/20.0}" ixy="0"  ixz="0"
               iyy="${object_1_mass/20.0}" iyz="0"
               izz="${object_1_mass/200.}" />
    </inertial> 
    <visual>
      <origin xyz="0.0 0.0 ${object_1_base_height/2}" rpy="0 0 0" />
      <geometry name="object_1_base_visual_geom">
        <box size="${object_1_base_width} ${object_1_base_width} ${object_1_base_height}" />
      </geometry>
    </visual> 
    <collision>
      <origin xyz="0.0 0.0 ${object_1_base_height/2}" rpy="0.0 0.0 0.0" />
      <geometry name="object_1_base_collision_geom">
        <box size="${object_1_base_width} ${object_1_base_width} ${object_1_base_height}" />
      </geometry>
    </collision>
  </link>
  <gazebo reference="object_1_base_link">
    <material>Gazebo/RustyBarrel</material>
    <mu1>0.1</mu1>
    <mu2>0.1</mu2>
    <kp>100000000.0</kp>
    <kd>1.0</kd>
    <selfCollide>true</selfCollide>
    <turnGravityOff>false</turnGravityOff>
    <dampingFactor>0.01</dampingFactor>
  </gazebo>
  -->
</robot>
