<?xml version="1.0"?>
<robot name="continuous_pendulum"
       xmlns:xi="http://www.w3.org/2001/XInclude"
       xmlns:gazebo="http://playerstage.sourceforge.net/gazebo/xmlschema/#gz"
       xmlns:model="http://playerstage.sourceforge.net/gazebo/xmlschema/#model"
       xmlns:sensor="http://playerstage.sourceforge.net/gazebo/xmlschema/#sensor"
       xmlns:body="http://playerstage.sourceforge.net/gazebo/xmlschema/#body"
       xmlns:geom="http://playerstage.sourceforge.net/gazebo/xmlschema/#geom"
       xmlns:joint="http://playerstage.sourceforge.net/gazebo/xmlschema/#joint"
       xmlns:interface="http://playerstage.sourceforge.net/gazebo/xmlschema/#interface"
       xmlns:rendering="http://playerstage.sourceforge.net/gazebo/xmlschema/#rendering"
       xmlns:renderable="http://playerstage.sourceforge.net/gazebo/xmlschema/#renderable"
       xmlns:controller="http://playerstage.sourceforge.net/gazebo/xmlschema/#controller"
       xmlns:physics="http://playerstage.sourceforge.net/gazebo/xmlschema/#physics">

  <!--
     A pendulum constructed from single continuous link and a mass with some moment of inertia
  -->
  <link name="world"/>
  <joint name="link1_joint" type="continuous" >
    <axis xyz="1 0 0" />
    <parent link="world" />
    <origin xyz="0 0 3" rpy="0 0 0" />
    <child link="link1" />
    <dynamics damping="0.0" />
  </joint>
  <link name="link1">
    <inertial >
      <mass value="1.0" />
      <origin xyz="0 1 0" /> 
      <inertia  ixx="0.0" ixy="0.0"  ixz="0.0"  iyy="0.0"  iyz="0.0"  izz="0.0" />
    </inertial>
    <visual >
      <origin xyz="0 0.5 0" rpy="0 0 0" />
      <geometry>
        <box size="0.2 1.0 0.2" />
      </geometry>
    </visual>
    <collision >
      <origin xyz="0 0.5 0" rpy="0 0 0" />
      <geometry>
        <box size="0.2 1.0 0.2" />
      </geometry>
    </collision>
  </link>
  <gazebo reference="link1">
    <material>Gazebo/GrassFloor</material>
    <turnGravityOff>false</turnGravityOff>
  </gazebo>

  <joint name="link2_joint" type="continuous" >
    <axis xyz="1 0 0" />
    <parent link="link1" />
    <origin xyz="0 1 0" rpy="0 0 0" />
    <child link="link2" />
    <dynamics damping="0.0" />
  </joint>
  <link name="link2">
    <inertial >
      <mass value="1.0" />
      <origin xyz="0 1 0" /> 
      <inertia  ixx="0.0" ixy="0.0"  ixz="0.0"  iyy="0.0"  iyz="0.0"  izz="0.0" />
    </inertial>
    <visual >
      <origin xyz="0 0.5 0" rpy="0 0 0" />
      <geometry>
        <box size="0.2 1.0 0.2" />
      </geometry>
    </visual>
    <collision >
      <origin xyz="0 0.5 0" rpy="0 0 0" />
      <geometry>
        <box size="0.2 1.0 0.2" />
      </geometry>
    </collision>
  </link>
  <gazebo reference="link2">
    <material>Gazebo/LightWood</material>
    <turnGravityOff>false</turnGravityOff>
  </gazebo>
  <gazebo>
      <!-- PR2_ACTARRAY -->
      <controller:gazebo_ros_controller_manager name="gazebo_ros_controller_manager" plugin="libgazebo_ros_controller_manager.so">
        <alwaysOn>true</alwaysOn>
        <updateRate>1000.0</updateRate>
        <interface:audio name="gazebo_ros_controller_manager_dummy_iface" />
      </controller:gazebo_ros_controller_manager>

      <!-- gazebo_ros_p3d for position groundtruth -->
      <controller:gazebo_ros_p3d name="p3d_link1_controller" plugin="libgazebo_ros_p3d.so">
          <alwaysOn>true</alwaysOn>
          <updateRate>100.0</updateRate>
          <bodyName>link1</bodyName>
          <topicName>link1_pose</topicName>
          <frameName>map</frameName>
          <interface:position name="p3d_link1_position"/>
      </controller:gazebo_ros_p3d>
      <controller:gazebo_ros_p3d name="p3d_link2_controller" plugin="libgazebo_ros_p3d.so">
          <alwaysOn>true</alwaysOn>
          <updateRate>100.0</updateRate>
          <bodyName>link2</bodyName>
          <topicName>link2_pose</topicName>
          <frameName>map</frameName>
          <interface:position name="p3d_link2_position"/>
      </controller:gazebo_ros_p3d>
  </gazebo>

  <!-- mechanism controls -->
  <transmission type="SimpleTransmission" name="link1_trans">
    <actuator name="link1_motor" />
    <joint name="link1_joint" />
    <mechanicalReduction>1</mechanicalReduction>
    <motorTorqueConstant>1</motorTorqueConstant>
  </transmission>

  <transmission type="SimpleTransmission" name="link2_trans">
    <actuator name="link2_motor" />
    <joint name="link2_joint" />
    <mechanicalReduction>1</mechanicalReduction>
    <motorTorqueConstant>1</motorTorqueConstant>
  </transmission>

</robot>
