<?xml version="1.0"?>
<robot name="pr2"
       xmlns:xi="http://www.w3.org/2001/XInclude"
       xmlns:gazebo="http://playerstage.sourceforge.net/gazebo/xmlschema/#gz"
       xmlns:model="http://playerstage.sourceforge.net/gazebo/xmlschema/#model"
       xmlns:sensor="http://playerstage.sourceforge.net/gazebo/xmlschema/#sensor"
       xmlns:body="http://playerstage.sourceforge.net/gazebo/xmlschema/#body"
       xmlns:geom="http://playerstage.sourceforge.net/gazebo/xmlschema/#geom"
       xmlns:joint="http://playerstage.sourceforge.net/gazebo/xmlschema/#joint"
       xmlns:interface="http://playerstage.sourceforge.net/gazebo/xmlschema/#interface"
       xmlns:rendering="http://playerstage.sourceforge.net/gazebo/xmlschema/#rendering"
       xmlns:renderable="http://playerstage.sourceforge.net/gazebo/xmlschema/#renderable"
       xmlns:controller="http://playerstage.sourceforge.net/gazebo/xmlschema/#controller"
       xmlns:physics="http://playerstage.sourceforge.net/gazebo/xmlschema/#physics">


  


  <link name="world"/>
  <joint name="base_block_joint" type="fixed">
    <parent link="world" />
    <origin xyz="0 0 0" rpy="0 0 0" />
    <child link="base_block" />
  </joint> 
  <link name="base_block">
    <inertial>
      <mass value="1000" />
      <origin xyz="0 0 0" />
      <inertia ixx="100"  ixy="0"  ixz="0" iyy="100" iyz="0" izz="100" />
    </inertial> 
    <visual>
      <origin xyz="0 0 0" rpy="0 0 0" />
      <geometry>
        <box size="0.001 0.001 0.001" />
      </geometry>
    </visual> 
    <collision>
      <origin xyz="0 0 0" rpy="0.0 0.0 0.0" />
      <geometry>
        <box size="0.001 0.001 0.001" />
      </geometry>
    </collision>
  </link>
  <gazebo reference="base_block">
    <material>Gazebo/GrassFloor</material>
  </gazebo>
  
  <joint name="link1_joint" type="revolute" >
    <axis xyz="0 0 1" />
    <limit lower="0.0" upper="0.0" effort="100" velocity="5" />
    <parent link="base_block" />
    <origin xyz="0 0 2" rpy="0 0 0" />
    <child link="link1" />
  </joint>
  <link name="link1">
    <inertial >
      <mass value="0.1" />
      <origin xyz="0 0 -0.5" /> 
      <inertia  ixx="0.1" ixy="0.0"  ixz="0.0"  iyy="0.1"  iyz="0.0"  izz="0.1" />
    </inertial>
    <visual >
      <origin xyz="0 0 -0.5" rpy="0 0 0" />
      <geometry>
        <box size="0.1 0.1 1.0" />
      </geometry>
    </visual>
    <collision >
      <origin xyz="0 0 -0.5" rpy="0.0 0.0 0.0" />
      <geometry>
        <box size="0.1 0.1 1.0" />
      </geometry>
    </collision>
  </link>
  <gazebo reference="link1">
    <material>Gazebo/Red</material>
    <turnGravityOff>false</turnGravityOff>
  </gazebo>


  <joint name="link2_joint" type="continuous" >
    <axis xyz="0 1 0" />
    <limit effort="100" velocity="5" />
    <dynamics damping="0.0" friction="0.0" />
    <parent link="link1" />
    <origin xyz="0 0 0" rpy="0 90 0" />
    <child link="link2" />
  </joint>
  <link name="link2">
    <inertial >
      <mass value="1.0" />
      <origin xyz="0 0 0.5" /> 
      <inertia  ixx="1.0" ixy="0.0"  ixz="0.0"  iyy="1.0"  iyz="0.0"  izz="1.0" />
    </inertial>
    <visual >
      <origin xyz="0 0 0.5" rpy="0 0 0" />
      <geometry>
        <cylinder radius="0.05" length="1.0" />
      </geometry>
    </visual>
    <collision >
      <origin xyz="0 0 0.5" rpy="0 0 0" />
      <geometry>
        <cylinder radius="0.05" length="1.0" />
      </geometry>
    </collision>
  </link>
  <gazebo reference="link2">
    <material>Gazebo/Blue</material>
    <turnGravityOff>false</turnGravityOff>
  </gazebo>

  <!-- mechanism controls -->
  <include filename="./dual_link.transmission.xacro" />
  
  <gazebo>
      <!-- pr2_actarray -->
      <controller:gazebo_ros_controller_manager name="gazebo_ros_controller_manager" plugin="libgazebo_ros_controller_manager.so">
        <alwaysOn>true</alwaysOn>
        <updateRate>1000.0</updateRate>
      </controller:gazebo_ros_controller_manager>

      <!-- gazebo_ros_p3d for position groundtruth -->
      <controller:gazebo_ros_p3d name="p3d_link1_controller" plugin="libgazebo_ros_p3d.so">
          <alwaysOn>true</alwaysOn>
          <updateRate>1000.0</updateRate>
          <bodyName>link1</bodyName>
          <topicName>link1_pose</topicName>
          <frameName>map</frameName>
          <xyzOffsets>0 0 0.0</xyzOffsets>
          <rpyOffsets>0 0 0.0</rpyOffsets>
          <interface:position name="p3d_link1_position"/>
      </controller:gazebo_ros_p3d>

      <!-- gazebo_ros_p3d for position groundtruth -->
      <controller:gazebo_ros_p3d name="p3d_link2_controller" plugin="libgazebo_ros_p3d.so">
          <alwaysOn>true</alwaysOn>
          <updateRate>1000.0</updateRate>
          <bodyName>link2</bodyName>
          <topicName>link2_pose</topicName>
          <frameName>map</frameName>
          <interface:position name="p3d_link2_position"/>
      </controller:gazebo_ros_p3d>
  </gazebo>
</robot>
