<?xml version="1.0"?>
<robot name="pr2"
       xmlns:xi="http://www.w3.org/2001/XInclude"
       xmlns:gazebo="http://playerstage.sourceforge.net/gazebo/xmlschema/#gz"
       xmlns:model="http://playerstage.sourceforge.net/gazebo/xmlschema/#model"
       xmlns:sensor="http://playerstage.sourceforge.net/gazebo/xmlschema/#sensor"
       xmlns:body="http://playerstage.sourceforge.net/gazebo/xmlschema/#body"
       xmlns:geom="http://playerstage.sourceforge.net/gazebo/xmlschema/#geom"
       xmlns:joint="http://playerstage.sourceforge.net/gazebo/xmlschema/#joint"
       xmlns:interface="http://playerstage.sourceforge.net/gazebo/xmlschema/#interface"
       xmlns:rendering="http://playerstage.sourceforge.net/gazebo/xmlschema/#rendering"
       xmlns:renderable="http://playerstage.sourceforge.net/gazebo/xmlschema/#renderable"
       xmlns:controller="http://playerstage.sourceforge.net/gazebo/xmlschema/#controller"
       xmlns:physics="http://playerstage.sourceforge.net/gazebo/xmlschema/#physics">

  <joint name="base_block_joint" type="fixed"> 
    <parent link="world" />
    <origin xyz="0 0 0.002 " rpy="0 0 0" />
    <child link="base_block" />
  </joint>
  <link name="base_block">
    <inertial>
      <mass value="1000" />
      <origin xyz="0 0 0" />
      <inertia ixx="100"  ixy="0"  ixz="0" iyy="100" iyz="0" izz="100" />
    </inertial> 
    <visual>
      <origin xyz="0 0 0" rpy="0 0 0" />
      <geometry name="base_block_visual_geom">
        <box size="0.001 0.001 0.001" />
      </geometry>
    </visual> 
    <collision>
      <origin xyz="0 0 0" rpy="0.0 0.0 0.0" />
      <geometry name="base_block_collision_geom">
        <box size="0.001 0.001 0.001" />
      </geometry>
    </collision>
  </link>
  <gazebo reference="base_block">
    <material>Gazebo/GrassFloor</material>
  </gazebo>
  
  <joint name="link1_joint" type="revolute" >
    <axis xyz="1 0 0" />
    <limit upper="-3" lower="3" effort="100" velocity="5" />
    <parent link="base_block" />
    <origin xyz="0 0 1" rpy="0 0 0" />
    <child link="link1" />
  </joint>
  <link name="link1">
    <inertial >
      <mass value="10" />
      <origin xyz="0 0 0" /> 
      <inertia  ixx="1.0" ixy="0.0"  ixz="0.0"  iyy="0.1"  iyz="0.0"  izz="0.1" />
    </inertial>
    <visual >
      <origin xyz="0 0 0" rpy="0 0 0" />
      <geometry name="sholder_roll_mesh_file">
        <box size="1.0 0.3 0.3" />
      </geometry>
    </visual>
    <collision >
      <origin xyz="0.5 0 0" rpy="0.0 0.0 0.0 " />
      <geometry name="link1_collision_geom">
        <box size="1.0 0.3 0.3" />
      </geometry>
    </collision>
  </link>
  <gazebo reference="link1">
    <material>Gazebo/Red</material>
    <turnGravityOff>true</turnGravityOff>
  </gazebo>

  <gazebo>
      <controller:ros_time name="ros_time" plugin="libros_time.so">
        <alwaysOn>true</alwaysOn>
        <updateRate>100.0</updateRate>
        <interface:audio name="dummy_ros_time_iface_should_not_be_here"/>
      </controller:ros_time>

      <!-- PR2_ACTARRAY -->
      <controller:ros_controller_manager name="ros_controller_manager" plugin="libros_controller_manager.so">
        <alwaysOn>true</alwaysOn>
        <updateRate>100.0</updateRate>
        <interface:audio name="ros_controller_manager_dummy_iface" />
      </controller:ros_controller_manager>

      <!-- ros_p3d for position groundtruth -->
      <controller:ros_p3d name="p3d_link1_controller" plugin="libros_p3d.so">
          <alwaysOn>true</alwaysOn>
          <updateRate>100.0</updateRate>
          <bodyName>link1</bodyName>
          <topicName>link1_pose</topicName>
          <frameName>map</frameName>
          <interface:position name="p3d_link1_position"/>
      </controller:ros_p3d>
  </gazebo>
  <!-- mechanism controls -->
  <include filename="./single_link.transmission.xacro" />

</robot>
